> error: Tracer failed: *"exit_status":-6,*,"message":"terminate called after throwing an instance of 'std::out_of_range*libdnf5*
*
testlib.Error: FAIL: Test completed, but found unexpected journal messages:
Process *python3) of user 0 terminated abnormally without generating a coredump.
